ZoomLauncher started.
Zoom path is: /opt/zoom
cmd line: --url=https://us05web.zoom.us/j/83218283606?pwd=TbeZvV8rMi0ikCJHDfCFSPhh3mmeEv.1
Start subprocess: /opt/zoom/zoom sucessfully,  process pid: 179 
                             Class      App      Lib Possible Culprit Flags
                resip::Connection      656      656 
                      resip::Data       36       36 
                 resip::DnsResult     1080     1080 
                   resip::Headers        1        1 
          resip::MsgHeaderScanner       40       40 
                resip::SipMessage     5224     5224 
         resip::TransportSelector      896      896 
                     resip::Tuple      128      128 
              resip::UdpTransport     1144     1144 
          resip::GenericIPAddress       28       28 

zoom started.
Traceback (most recent call last):
  File "/usr/local/lib/python3.8/dist-packages/pyautogui/__init__.py", line 172, in wrapper
    return wrappedFunction(*args, **kwargs)
  File "/usr/local/lib/python3.8/dist-packages/pyautogui/__init__.py", line 204, in locateCenterOnScreen
    return pyscreeze.locateCenterOnScreen(*args, **kwargs)
  File "/usr/local/lib/python3.8/dist-packages/pyscreeze/__init__.py", line 447, in locateCenterOnScreen
    coords = locateOnScreen(image, **kwargs)
  File "/usr/local/lib/python3.8/dist-packages/pyscreeze/__init__.py", line 405, in locateOnScreen
    retVal = locate(image, screenshotIm, **kwargs)
  File "/usr/local/lib/python3.8/dist-packages/pyscreeze/__init__.py", line 383, in locate
    points = tuple(locateAll(needleImage, haystackImage, **kwargs))
  File "/usr/local/lib/python3.8/dist-packages/pyscreeze/__init__.py", line 257, in _locateAll_opencv
    raise ImageNotFoundException('Could not locate the image (highest confidence = %.3f)' % result.max())
pyscreeze.ImageNotFoundException: Could not locate the image (highest confidence = 0.308)

During handling of the above exception, another exception occurred:

Traceback (most recent call last):
  File "/home/zoomrec/zoomrec.py", line 1047, in <module>
    main()
  File "/home/zoomrec/zoomrec.py", line 1034, in main
    join_ongoing_meeting()
  File "/home/zoomrec/zoomrec.py", line 928, in join_ongoing_meeting
    join(meet_id=event["id"], meet_pw=event["password"],
  File "/home/zoomrec/zoomrec.py", line 502, in join
    if wrap(pyautogui.locateCenterOnScreen(os.path.join(IMG_PATH, img_name), confidence=0.9)):
  File "/usr/local/lib/python3.8/dist-packages/pyautogui/__init__.py", line 174, in wrapper
    raise ImageNotFoundException  # Raise PyAutoGUI's ImageNotFoundException.
pyautogui.ImageNotFoundException
No PulseAudio daemon running, or not running as session daemon.
                             Class      App      Lib Possible Culprit Flags
                resip::Connection      656      656 
                      resip::Data       36       36 
                 resip::DnsResult     1080     1080 
                   resip::Headers        1        1 
          resip::MsgHeaderScanner       40       40 
                resip::SipMessage     5224     5224 
         resip::TransportSelector      896      896 
                     resip::Tuple      128      128 
              resip::UdpTransport     1144     1144 
          resip::GenericIPAddress       28       28 

                             Class      App      Lib Possible Culprit Flags
                resip::Connection      656      656 
                      resip::Data       36       36 
                 resip::DnsResult     1080     1080 
                   resip::Headers        1        1 
          resip::MsgHeaderScanner       40       40 
                resip::SipMessage     5224     5224 
         resip::TransportSelector      896      896 
                     resip::Tuple      128      128 
              resip::UdpTransport     1144     1144 
          resip::GenericIPAddress       28       28 

zoom started.
zoom started.
Client: Breakpad is using Single Client Mode! client fd = -1
QStandardPaths: XDG_RUNTIME_DIR not set, defaulting to '/tmp/runtime-zoomrec'
libva error: /usr/lib/x86_64-linux-gnu/dri/i965_drv_video.so init failed
libva error: /usr/lib/x86_64-linux-gnu/dri/i965_drv_video.so init failed
                             Class      App      Lib Possible Culprit Flags
                resip::Connection      656      656 
                      resip::Data       36       36 
                 resip::DnsResult     1080     1080 
                   resip::Headers        1        1 
          resip::MsgHeaderScanner       40       40 
                resip::SipMessage     5224     5224 
         resip::TransportSelector      896      896 
                     resip::Tuple      128      128 
              resip::UdpTransport     1144     1144 
          resip::GenericIPAddress       28       28 

zoom started.
[CZPClientLogMgr::LogClientEnvironment] [MacAddr: 02:42:AC:11:00:02][client: Linux][OS:  Ubuntu 20.04.5 LTS x64][Hardware: CPU Core:2 Frenquency:2.6 G Memory size:7766MB CPU Brand:       Intel(R) Core(TM) i5-3320M CPU @ 2.60GHz GPU Brand:][Req ID: ]


